Workbook

Sheet 機能一覧
P1: 自動化対象 | S1: 修正フラグ
A2: ID | B2: 画面 | C2: 機能 | F2: 備考 | G2: 重要度(*1) | H2: バリエーション | I2: 備考 | J2: 前提条件 | K2: 確認手順 | L2: 確認内容 | M2: 実施者 | N2: 結果 | P2: 関数 | Q2: 値のみ ※誤修正した場合のバックアップ | S2: 追加 | T2: 修正
A3: 1 | B3: ログイン | C3: ログイン | D3: 多要素認証(無効) | G3: A | J3: ・ログイン画面を表示していること ・多要素認証を無効にしているアカウントがあること | K3: 1.ズメーンに登録済みのメールアドレスとパスワードを入力する 2.「続ける」を押下する | L3: ・入力したアカウントでログインできること | M3: Auto | N3: 自動化 | P3: =IF(ISNUMBER(SEARCH("Auto",M3)),"〇","×") -> 〇 | Q3: 〇
A4: =A3+1 -> 2 | B4: ログイン | C4: ログイン | D4: 多要素認証(有効) | G4: A | J4: ・ログイン画面を表示していること ・多要素認証を有効にしているアカウントがあること | K4: 1.ズメーンに登録済みのメールアドレスとパスワードを入力する 2.「続ける」を押下する 3.認証アプリを使用して、ワンタイムコードの入力を行う 4.「続ける」を押下する 5.「続ける」を押下する | L4: ・入力したアカウントでログインできること | M4: Auto | N4: 自動化 | P4: =IF(ISNUMBER(SEARCH("Auto",M4)),"〇","×") -> 〇 | Q4: 〇
A5: =A4+1 -> 3 | B5: ログイン | C5: パスワードリセット | G5: B | I5: ※パスワードリセット宛のメールが届くため、受信を確認できるメールアドレスで実施する | J5: ・ログイン画面を表示していること | K5: 1.「パスワードをお忘れですか？」を押下する 2.ズメーンに登録済みのメールアドレスを入力する 3.「続ける」を押下する 4.受信した【ズメーン】パスワードの変更の「こちら」を押下する 5.新しいパスワードと新しいパスワードの再入力に同値を入力する 6.「パスワードのリセット」を押下する 7.メールアドレスと変更したパスワードでズメーンにログインを行う | L5: ・入力したアカウントでログインできること | M5: Auto | N5: 自動化 | P5: =IF(ISNUMBER(SEARCH("Auto",M5)),"〇","×") -> 〇 | Q5: 〇
A6: =A5+1 -> 4 | B6: フリーワード検索 | C6: 図面⇔ファイル切り替え | G6: A | J6: ・図面フリーワード検索画面を表示していること | K6: 1.ラジオボタンの「ファイル」を押下する 2.ラジオボタンの「図面」を押下する | L6: ・図面とファイルのフリーワード検索が切り替わること | N6: 未実施 | P6: =IF(ISNUMBER(SEARCH("Auto",M6)),"〇","×") -> × | Q6: ×
A7: =A6+1 -> 5 | B7: フリーワード検索 | C7: 図面 | D7: 検索 | G7: A | I7: ※入力した内容による検索パターンはチケットテスト時に行う | J7: ・図面フリーワード検索画面を表示していること | K7: 1.任意の値を入力する | L7: ・検索内容にヒットした図面が表示されること | N7: 未実施 | P7: =IF(ISNUMBER(SEARCH("Auto",M7)),"〇","×") -> × | Q7: ×
A8: =A7+1 -> 6 | B8: フリーワード検索 | C8: 図面 | D8: 絞り込み | G8: A | J8: 同上 | K8: 2.「絞り込み」を押下する 3.任意の期間を選択する | L8: ・選択した期間の登録日の図面のみ表示されること | N8: 未実施 | P8: =IF(ISNUMBER(SEARCH("Auto",M8)),"〇","×") -> × | Q8: ×
A9: =A8+1 -> 7 | B9: フリーワード検索 | C9: 図面 | D9: 並び順 | G9: A | J9: 同上 | K9: 4.「並び順」を押下する 5.任意の順を選択する | L9: ・選択した並び順の通りに表示されること | N9: 未実施 | P9: =IF(ISNUMBER(SEARCH("Auto",M9)),"〇","×") -> × | Q9: ×
A10: =A9+1 -> 8 | B10: フリーワード検索 | C10: ファイル | D10: 検索 | G10: A | I10: ※入力した内容による検索パターンはチケットテスト時に行う | J10: ・ファイルフリーワード検索画面を表示していること | K10: 1.任意の値を入力する | L10: ・検索内容にヒットしたファイルが表示されること | N10: 未実施 | P10: =IF(ISNUMBER(SEARCH("Auto",M10)),"〇","×") -> × | Q10: ×
A11: =A10+1 -> 9 | B11: フリーワード検索 | C11: ファイル | D11: 絞り込み | G11: A | J11: 同上 | K11: 2.「絞り込み」を押下する 3.任意の期間を選択する 4.任意の種別を選択する | L11: ・選択した期間の登録日と種別のファイルのみ表示されること | N11: 未実施 | P11: =IF(ISNUMBER(SEARCH("Auto",M11)),"〇","×") -> × | Q11: ×
A12: =A11+1 -> 10 | B12: フリーワード検索 | C12: ファイル | D12: 並び順 | G12: A | J12: 同上 | K12: 5.「並び順」を押下する 6.任意の順を選択する | L12: ・選択した並び順の通りに表示されること | N12: 未実施 | P12: =IF(ISNUMBER(SEARCH("Auto",M12)),"〇","×") -> × | Q12: ×
A13: =A12+1 -> 11 | B13: 図面一覧 | C13: 一括操作 | D13: 選択 | E13: 単一選択 | G13: A | J13: ・図面一覧画面を表示していること | K13: 1.「一括操作」を押下する 2.任意の図面を押下する 3.手順2と同様の図面を押下する | L13: ・図面の選択/未選択が切り替わること | N13: 未実施 | P13: =IF(ISNUMBER(SEARCH("Auto",M13)),"〇","×") -> × | Q13: ×
A14: =A13+1 -> 12 | B14: 図面一覧 | C14: 一括操作 | D14: 選択 | E14: 全選択 | G14: A | J14: ・図面一覧画面を表示していること | K14: 1.「一括操作」を押下する 2.「全選択」を押下する 3.「全選択」を押下する | L14: ・同ページ内の図面の選択/未選択が切り替わること | N14: 未実施 | P14: =IF(ISNUMBER(SEARCH("Auto",M14)),"〇","×") -> × | Q14: ×
A15: =A14+1 -> 13 | B15: 図面一覧 | C15: 一括操作 | D15: 新規案件作成 | E15: すべての行に反映 | G15: A | J15: 同上 | K15: 1.「一括操作」を押下する 2.任意の図面を押下する 3.「新規案件作成」を押下する 4.最上部の行に任意の値を入力・選択する 5.「すべての行に反映」を押下する | L15: ・最上部の行の値がすべての案件に反映されること | N15: 未実施 | P15: =IF(ISNUMBER(SEARCH("Auto",M15)),"〇","×") -> × | Q15: ×
A16: =A15+1 -> 14 | B16: 図面一覧 | C16: 一括操作 | D16: 新規案件作成 | E16: 手入力 | G16: A | J16: 同上 | K16: 6.案件行に任意の値を入力・選択する | L16: ・入力・選択した通りに値が入力できること | N16: 未実施 | P16: =IF(ISNUMBER(SEARCH("Auto",M16)),"〇","×") -> × | Q16: ×
A17: =A16+1 -> 15 | B17: 図面一覧 | C17: 一括操作 | D17: 新規案件作成 | G17: A | I17: ※すべて同一のステータスの場合は該当タブ、それ以外の場合は「すべてタブ」 | J17: 同上 | K17: 7.「案件を作成する」を押下する 8.「案件一覧に移動する」を押下する | L17: ・入力した値の通りに新規案件が作成されること ・案件一覧画面に遷移すること | N17: 未実施 | P17: =IF(ISNUMBER(SEARCH("Auto",M17)),"〇","×") -> × | Q17: ×
A18: =A17+1 -> 16 | B18: 図面一覧 | C18: 一括操作 | D18: ファイル追加 | G18: B | J18: ・図面一覧画面を表示していること | K18: 1.「一括操作」を押下する 2.任意の図面を押下する 3.「ファイル追加」を押下する 4.図面と関連資料で任意のファイルを選択する 5.「保存する」を押下する | L18: ・選択した図面にファイルの追加をできること | N18: 未実施 | P18: =IF(ISNUMBER(SEARCH("Auto",M18)),"〇","×") -> × | Q18: ×
A19: =A18+1 -> 17 | B19: 図面一覧 | C19: 一括操作 | D19: ファイル追加 | G19: B | I19: タブレットで実施 ※実施するOS/機種については別途相談 | J19: ・図面一覧画面を表示していること | K19: 1.「一括操作」を押下する 2.任意の図面を押下する 3.「ファイル追加」を押下する 4.「ファイルを選択」を押下する 5.「写真ライブラリ」を押下する 6.任意の写真を選択する 7.「保存する」を押下する | L19: ・写真ライブラリからアップロードできること | N19: 未実施 | P19: =IF(ISNUMBER(SEARCH("Auto",M19)),"〇","×") -> × | Q19: ×
A20: =A19+1 -> 18 | B20: 図面一覧 | C20: 一括操作 | D20: ファイル追加 | E20: 写真を撮る(タブレット) ※関連資料は録画も | G20: B | I20: タブレットで実施 ※実施するOS/機種については別途相談 | J20: ・図面一覧画面を表示していること | K20: 1.「一括操作」を押下する 2.任意の図面を押下する 3.「ファイル追加」を押下する 4.「ファイルを選択」を押下する 5.「写真を撮る」を押下する 6.写真の撮影を行う 7.「保存する」を押下する | L20: ・撮影した写真をアップロードできること | N20: 未実施 | P20: =IF(ISNUMBER(SEARCH("Auto",M20)),"〇","×") -> × | Q20: ×
A21: =A20+1 -> 19 | B21: 図面一覧 | C21: 一括操作 | D21: 図面項目編集 | G21: B | J21: ・図面一覧画面を表示していること | K21: 1.「一括操作」を押下する 2.任意の図面を押下する 3.「図面項目編集」を押下する 4.任意の項目を選択する 5.「次へ」を押下する 6.任意の値を入力/選択する 7.「保存する」を押下する | L21: ・変更内容が反映されること | N21: 未実施 | P21: =IF(ISNUMBER(SEARCH("Auto",M21)),"〇","×") -> × | Q21: ×
A22: =A21+1 -> 20 | B22: 図面一覧 | C22: 一括操作 | D22: 連続書込 | G22: A | J22: ・図面一覧画面を表示していること | K22: 1.「一括操作」を押下する 2.任意の図面を複数押下する 3.「連続書込」を押下する 4.任意の書き込みを行う 5.書き込んだオブジェクトをコピーする(ctrl + c or cmd + c) 6.「新しいファイルとして保存して次へ」を押下する 7.コピーしたオブジェクトををペーストする(ctrl + v or cmd + v) 8.「新しいファイルとして保存して終了」を押下する | L22: ・ファイルを跨いだオブジェクトのコピペができ、書きこも保存後のプレビューが正常に表示されること | N22: 未実施 | P22: =IF(ISNUMBER(SEARCH("Auto",M22)),"〇","×") -> × | Q22: × | S22: 〇
A23: =A22+1 -> 21 | B23: 図面一覧 | C23: 一括操作 | D23: 最新図面印刷 | G23: B | J23: ・図面一覧画面を表示していること | K23: 1.「一括操作」を押下する 2.任意の図面を押下する 3.「最新図面印刷」を押下する | L23: ・選択した図面の印刷プレビューが表示されること | N23: 未実施 | P23: =IF(ISNUMBER(SEARCH("Auto",M23)),"〇","×") -> × | Q23: ×
A24: =A23+1 -> 22 | B24: 図面一覧 | C24: 一括操作 | D24: 最新図面ダウンロード | G24: B | J24: ・図面一覧画面を表示していること | K24: 1.「一括操作」を押下する 2.任意の図面を押下する 3.「最新図面ダウンロード」を押下する | L24: ・選択した図面の最新図面がすべてダウンロードできること | N24: 未実施 | P24: =IF(ISNUMBER(SEARCH("Auto",M24)),"〇","×") -> × | Q24: ×
A25: =A24+1 -> 23 | B25: 図面一覧 | C25: 一括操作 | D25: 一括削除 | G25: B | J25: ・図面一覧画面を表示していること | K25: 1.「一括操作」を押下する 2.任意の図面を押下する 3.「削除」を押下する 4."delete"と入力する 5.「削除する」を押下する | L25: ・選択した図面をすべて削除できること | N25: 未実施 | P25: =IF(ISNUMBER(SEARCH("Auto",M25)),"〇","×") -> × | Q25: ×
A26: =A25+1 -> 24 | B26: 図面一覧 | C26: 新しい図面を追加 | D26: ファイル選択(ボタン) | E26: 組図保存なし | F26: ※他画面でのファイル追加と合わせてファイル形式を網羅できるようにする？ | G26: A | H26: PDF AI 2D-CAD：DXF, DWG 画像：JPG, JPEG, JPE, BMP, HEIC, HEIF, GIF, PNG, TIF, TIFF, SVG | I26: ※図面詳細画面とファイル形式をわけて実施 | J26: ・図面一覧画面を表示していること ・自動登録しない、AIにおまかせ、ファイル名から登録で設定している項目があること | K26: 1.「新しい図面を追加」を押下する 2.ファイルを選択する 3.図面基本項目、図面詳細項目に任意の値を入力する 4.「さらにファイルを選択」を押下する 5.任意のファイルを選択する 6.「保存する」を押下する | L26: ・新しい図面を追加でき、入力した項目が反映されていること ・自動登録設定に応じた内容が入力・設定されていること ※図面詳細項目の文字項目に登録データのリストが表示されること | N26: 未実施 | P26: =IF(ISNUMBER(SEARCH("Auto",M26)),"〇","×") -> × | Q26: × | T26: 〇
A27: =A26+1 -> 25 | B27: 図面一覧 | C27: 新しい図面を追加 | D27: ドラック＆ドロップ | E27: 組図保存あり | F27: 同上 | G27: A | H27: 同上 | I27: 同上 | J27: ・図面一覧画面を表示していること | K27: 1.「新しい図面を追加」を押下する 2.ドラック＆ドロップ操作で2ファイル以上追加する 3.図面基本項目、図面詳細項目に任意の値を入力する 4.「組図として保存する」を押下する 5.任意の図面を選択する 6.「組図として保存する」を押下する | L27: ・新しい図面を追加でき、入力した項目が反映されていること ・自動登録設定に応じた内容が入力・設定されていること ・図面詳細の組図タブに遷移し、選択した図面が親図で他の図面が子図として追加されること | N27: 未実施 | P27: =IF(ISNUMBER(SEARCH("Auto",M27)),"〇","×") -> × | Q27: × | T27: 〇
A28: =A27+1 -> 26 | B28: 図面一覧 | C28: 新しい図面を追加 | D28: 写真ライブラリ(スマホ、タブレット) | G28: A | I28: スマホ、タブレットで実施 ※実施するOS/機種については別途相談 | J28: ・図面一覧画面を表示していること | K28: 1.「新しい図面を追加」を押下する 2.「ファイルを選択」を押下する 3.「写真ライブラリ」を押下する 4.任意の写真を選択する 5.「保存する」を押下する | L28: ・写真ライブラリからアップロードできること | N28: 未実施 | P28: =IF(ISNUMBER(SEARCH("Auto",M28)),"〇","×") -> × | Q28: ×
A29: =A28+1 -> 27 | B29: 図面一覧 | C29: 新しい図面を追加 | D29: 写真を撮る(スマホ、タブレット) | G29: A | I29: スマホ、タブレットで実施 ※実施するOS/機種については別途相談 | J29: ・図面一覧画面を表示していること | K29: 1.「新しい図面を追加」を押下する 2.「ファイルを選択」を押下する 3.「写真を撮る」を押下する 4.写真の撮影を行う 5.「保存する」を押下する | L29: ・撮影した写真をアップロードできること | N29: 未実施 | P29: =IF(ISNUMBER(SEARCH("Auto",M29)),"〇","×") -> × | Q29: ×
A30: =A29+1 -> 28 | B30: 図面一覧 | C30: 新しい図面を追加 | D30: ファイルを選択(スマホ、タブレット) | G30: A | I30: スマホ、タブレットで実施 ※実施するOS/機種については別途相談 | J30: ・図面一覧画面を表示していること | K30: 1.「新しい図面を追加」を押下する 2.「ファイルを選択」を押下する 3.「ファイルを選択」を押下する 4.任意のファイルを選択する 5.「保存する」を押下する | L30: ・ファイルからアップロードできること | N30: 未実施 | P30: =IF(ISNUMBER(SEARCH("Auto",M30)),"〇","×") -> × | Q30: ×
A31: =A30+1 -> 29 | B31: 図面一覧 | C31: PDFを分割+書き込み | G31: A | H31: PDF | J31: ・図面一覧画面を表示していること | K31: 1.「新しい図面を追加」を押下する 2.PDFファイルを選択する 3.「分割」を押下する 4.任意の分割を行う 5.任意のページ「このページを複製」を押下する 6.「書き込み」を押下する 7.任意の書き込みを行う 8.「+追加」を押下する 9.「保存する」を押下する 10.「分割された図面を新規追加」を押下する 11.図面基本項目、図面詳細項目に任意の値を入力する 12.「保存する」を押下する | L31: ・新しい図面を追加でき、入力した項目が反映されていること ・分割/書き込みが正しく反映されていること | N31: 未実施 | P31: =IF(ISNUMBER(SEARCH("Auto",M31)),"〇","×") -> × | Q31: × | T31: 〇
A32: =A31+1 -> 30 | B32: 図面一覧 | C32: 検索 | G32: A | J32: ・図面一覧画面を表示していること | K32: 1.検索内容の入力/選択を行う | L32: ・条件に一致する図面のみ表示されること | N32: 未実施 | P32: =IF(ISNUMBER(SEARCH("Auto",M32)),"〇","×") -> × | Q32: ×
A33: =A32+1 -> 31 | B33: 図面一覧 | C33: 検索 | D33: 画面更新 | G33: A | J33: 同上 | K33: 2.画面の更新を行う | L33: ・検索条件が保持され、正しい検索内容が表示されること | N33: 未実施 | P33: =IF(ISNUMBER(SEARCH("Auto",M33)),"〇","×") -> × | Q33: ×
A34: =A33+1 -> 32 | B34: 図面一覧 | C34: 並び替え | G34: A | H34: 登録日順、最終更新日時順、図番順、納品日(日付項目) | J34: ・図面一覧画面を表示していること | K34: 1.並び替えから表示順を選択する | L34: ・選択した並び順の通りに表示されること | N34: 未実施 | P34: =IF(ISNUMBER(SEARCH("Auto",M34)),"〇","×") -> × | Q34: ×
A35: =A34+1 -> 33 | B35: 図面一覧 | C35: 表示数 | G35: A | H35: 25件、50件、100件 | J35: ・図面一覧画面を表示していること | K35: 1.表示数から任意の件数を選択する | L35: ・選択した通りの件数で表示されること | N35: 未実施 | P35: =IF(ISNUMBER(SEARCH("Auto",M35)),"〇","×") -> × | Q35: ×
A36: =A35+1 -> 34 | B36: 図面一覧 | C36: 図面の未読管理 | D36: 未読 | G36: A | J36: ・図面一覧画面を表示していること | K36: 1.新規図面のアップロードを行う | L36: ・新規図面にNewアイコンが付くこと | N36: 未実施 | P36: =IF(ISNUMBER(SEARCH("Auto",M36)),"〇","×") -> × | Q36: ×
A37: =A36+1 -> 35 | B37: 図面一覧 | C37: 図面の未読管理 | D37: 未閲覧の新規図面のみ表示 | G37: A | J37: 同上 | K37: 2.「未閲覧の新規図面のみ表示」のチェックをONにする | L37: ・未読の図面のみ表示されること | N37: 未実施 | P37: =IF(ISNUMBER(SEARCH("Auto",M37)),"〇","×") -> × | Q37: ×
A38: =A37+1 -> 36 | B38: 図面一覧 | C38: 図面の未読管理 | D38: 既読 | G38: A | J38: 同上 | K38: 3.任意の図面を押下する 4.「←」を押下する | L38: ・該当図面が既読になること(Newアイコンが消える) | N38: 未実施 | P38: =IF(ISNUMBER(SEARCH("Auto",M38)),"〇","×") -> × | Q38: ×
A39: =A38+1 -> 37 | B39: 図面一覧 | C39: プレビュー表示 | G39: A | J39: ・図面一覧画面のリスト表示タブを表示していること | K39: 1.「プレビュー」を押下する | L39: ・プレビュー表示に切り替わること | N39: 未実施 | P39: =IF(ISNUMBER(SEARCH("Auto",M39)),"〇","×") -> × | Q39: ×
A40: =A39+1 -> 38 | B40: 図面一覧 | C40: リスト表示 | G40: A | J40: ・図面一覧画面のプレビュー表示タブを表示していること | K40: 1.「リスト」を押下する | L40: ・リスト表示に切り替わること | N40: 未実施 | P40: =IF(ISNUMBER(SEARCH("Auto",M40)),"〇","×") -> × | Q40: ×
...

Sheet 0823向け修正メモ
A1: チケット | B1: URL | C1: 追加済チェック
A2: 顧客名の「正式名称」を持てるようにする | B2: https://app.notion.com/p/fact-base/3a77b39bb0c8818dbb2bddd161c01e80 | C2: 済
A3: 書き込み：案件一覧で連続書き込み | B3: https://app.notion.com/p/fact-base/3a47b39bb0c880c18f04f77957e8cd11 | C3: 済
A22: ※動作上変わらないチケットは記載対象外

Sheet 集計
B1: ケース数
B3: A | C3: B | D3: C | E3: D | F3: 計
B4: =COUNTIF('機能一覧'!$G:$G,B3) -> 356 | C4: =COUNTIF('機能一覧'!$G:$G,C3) -> 109 | D4: =COUNTIF('機能一覧'!$G:$G,D3) -> 18 | E4: =COUNTIF('機能一覧'!$G:$G,E3) -> 43 | F4: =SUM(B4:E4) -> 526
B6: 実施結果
B8: ステータス | C8: A | D8: B | E8: C | F8: D | G8: 計
B9: 未実施 | C9: =COUNTIFS('機能一覧'!$G$3:$G$627,'集計'!C$8,'機能一覧'!$N$3:$N$627,'集計'!$B9) -> 234 | D9: =COUNTIFS('機能一覧'!$G$3:$G$627,'集計'!D$8,'機能一覧'!$N$3:$N$627,'集計'!$B9) -> 45 | E9: =COUNTIFS('機能一覧'!$G$3:$G$627,'集計'!E$8,'機能一覧'!$N$3:$N$627,'集計'!$B9) -> 7 | F9: =COUNTIFS('機能一覧'!$G$3:$G$627,'集計'!F$8,'機能一覧'!$N$3:$N$627,'集計'!$B9) -> 43 | G9: =SUM(C9:F9) -> 329
B10: OK | C10: =COUNTIFS('機能一覧'!$G$3:$G$627,'集計'!C$8,'機能一覧'!$N$3:$N$627,'集計'!$B10) -> 0 | D10: =COUNTIFS('機能一覧'!$G$3:$G$627,'集計'!D$8,'機能一覧'!$N$3:$N$627,'集計'!$B10) -> 0 | E10: =COUNTIFS('機能一覧'!$G$3:$G$627,'集計'!E$8,'機能一覧'!$N$3:$N$627,'集計'!$B10) -> 0 | F10: =COUNTIFS('機能一覧'!$G$3:$G$627,'集計'!F$8,'機能一覧'!$N$3:$N$627,'集計'!$B10) -> 0 | G10: =SUM(C10:F10) -> 0
B11: NG | C11: =COUNTIFS('機能一覧'!$G$3:$G$627,'集計'!C$8,'機能一覧'!$N$3:$N$627,'集計'!$B11) -> 0 | D11: =COUNTIFS('機能一覧'!$G$3:$G$627,'集計'!D$8,'機能一覧'!$N$3:$N$627,'集計'!$B11) -> 0 | E11: =COUNTIFS('機能一覧'!$G$3:$G$627,'集計'!E$8,'機能一覧'!$N$3:$N$627,'集計'!$B11) -> 0 | F11: =COUNTIFS('機能一覧'!$G$3:$G$627,'集計'!F$8,'機能一覧'!$N$3:$N$627,'集計'!$B11) -> 0 | G11: =SUM(C11:F11) -> 0
B12: 保留 | C12: =COUNTIFS('機能一覧'!$G$3:$G$627,'集計'!C$8,'機能一覧'!$N$3:$N$627,'集計'!$B12) -> 0 | D12: =COUNTIFS('機能一覧'!$G$3:$G$627,'集計'!D$8,'機能一覧'!$N$3:$N$627,'集計'!$B12) -> 0 | E12: =COUNTIFS('機能一覧'!$G$3:$G$627,'集計'!E$8,'機能一覧'!$N$3:$N$627,'集計'!$B12) -> 0 | F12: =COUNTIFS('機能一覧'!$G$3:$G$627,'集計'!F$8,'機能一覧'!$N$3:$N$627,'集計'!$B12) -> 0 | G12: =SUM(C12:F12) -> 0
B13: 対象外 | C13: =COUNTIFS('機能一覧'!$G$3:$G$627,'集計'!C$8,'機能一覧'!$N$3:$N$627,'集計'!$B13) -> 0 | D13: =COUNTIFS('機能一覧'!$G$3:$G$627,'集計'!D$8,'機能一覧'!$N$3:$N$627,'集計'!$B13) -> 0 | E13: =COUNTIFS('機能一覧'!$G$3:$G$627,'集計'!E$8,'機能一覧'!$N$3:$N$627,'集計'!$B13) -> 0 | F13: =COUNTIFS('機能一覧'!$G$3:$G$627,'集計'!F$8,'機能一覧'!$N$3:$N$627,'集計'!$B13) -> 0 | G13: =SUM(C13:F13) -> 0
B14: 自動化 | C14: =COUNTIFS('機能一覧'!$G$3:$G$627,'集計'!C$8,'機能一覧'!$N$3:$N$627,'集計'!$B14) -> 122 | D14: =COUNTIFS('機能一覧'!$G$3:$G$627,'集計'!D$8,'機能一覧'!$N$3:$N$627,'集計'!$B14) -> 64 | E14: =COUNTIFS('機能一覧'!$G$3:$G$627,'集計'!E$8,'機能一覧'!$N$3:$N$627,'集計'!$B14) -> 11 | F14: =COUNTIFS('機能一覧'!$G$3:$G$627,'集計'!F$8,'機能一覧'!$N$3:$N$627,'集計'!$B14) -> 0 | G14: =SUM(C14:F14) -> 197
